<?xml version="1.0"?>
<robot name="four_wheel_tower_robot" xmlns:xacro="http://www.ros.org/wiki/xacro">
    <xacro:include filename="$(find urdf_robots)/urdf/robot2.gazebo" />

    <link name="base_link" />
    <link name="chassis">
        <inertial>
            <origin xyz="0.0 0.0 0.0" rpy="0.0 0.0 0.0" />
            <mass value="5.0" />
            <inertia ixx="1.0" ixy="0.0" ixz="0.0" iyy="1.0" iyz="0.0" izz="1.0" />
        </inertial>
        <visual name="">
            <origin xyz="0.0 0.0 0.09" rpy="0.0 0.0 0.0" />
            <geometry>
                <box size="0.6 0.4 0.13" />
            </geometry>
            <material name="">
                <color rgba="1.0 1.3 2.0 1.0"/>
                <texture filename=""/>
            </material>
        </visual>
        <collision>
            <origin xyz="0.0 0.0 0.0" rpy="0.0 0.0 0.0" />
            <geometry>
                <box size="0.6 0.4 0.1" />
            </geometry>
        </collision>
    </link>
    <joint name="base_joint" type="fixed">
        <origin xyz="0.0 0.0 0.0" rpy="0.0 0.0 0.0" />
        <parent link="base_link" />
        <child link="chassis" />
    </joint>

<!--camera link-->
    <link name="camera">
        <inertial>
            <origin xyz="0.0 0.0 0.0" rpy="0.0 0.0 0.0"/>
            <mass value="0.0"/>
            <inertia ixx="1.0" ixy="0.0" ixz="0.0" iyy="1.0" iyz="0.0" izz="1.0"/>
        </inertial>
        <visual name="">
            <origin xyz="-0.18 0.0 0.49" rpy="0.0 0.0 0.0"/>
            <geometry>
                <box size="0.1 0.25 0.08"/>
            </geometry>
            <material name="">
                <color rgba="6.0 0.0 0.0 0.9"/>
                <texture filename=""/>
            </material>
        </visual>
        <collision>
            <origin xyz="-0.2 0.0 0.5" rpy="0.0 0.0 0.0"/>
            <geometry>
                <box size="0.15 0.25 0.1"/>
            </geometry>
        </collision>
    </link>
    <joint name="camera_to_tower_joint" type="fixed">
        <origin xyz="0.0 0.0 0.0" rpy="0.0 0.0 0.0"/>
        <parent link="camera_tower"/>
        <child link="camera"/>
        <axis xyz="0.0 0.0 0.0"/>
        <limit lower="0.0" upper="0.0" effort="0.0" velocity="0.0"/>
    </joint>

<!--camera tower-->

    <link name="camera_tower">
        <inertial>
            <origin xyz="0.0 0.0 0.0" rpy="0.0 0.0 0.0"/>
            <mass value="0.0"/>
            <inertia ixx="1.0" ixy="0.0" ixz="0.0" iyy="1.0" iyz="0.0" izz="1.0"/>
        </inertial>
        <visual name="">
            <origin xyz="-0.2 0.0 0.3" rpy="0.0 0.0 0.0"/>
            <geometry>
                <box size="0.04 0.12 0.3"/>
            </geometry>
            <material name="">
                <color rgba="1.0 0.0 0.0 1.0"/>
                <texture filename=""/>
            </material>
        </visual>
        <collision>
            <origin xyz="-0.2 0.0 0.3" rpy="0.0 0.0 0.0"/>
            <geometry>
                <box size="0.06 0.15 0.3"/>
            </geometry>
        </collision>
    </link>
    <joint name="chassis_to_tower_joint" type="fixed">
        <origin xyz="0.0 0.0 0.0" rpy="0.0 0.0 0.0"/>
        <parent link="chassis"/>
        <child link="camera_tower"/>
        <axis xyz="0.0 0.0 0.0"/>
    </joint>

<!--right wheel front-->

<link name="right_wheel_front">
        <inertial>
            <origin xyz="0.0 0.0 0.0" rpy="0.0 0.0 0.0" />
            <mass value="1.0" />
            <inertia ixx="1.0" ixy="0.0" ixz="0.0" iyy="1.0" iyz="0.0" izz="1.0" />
        </inertial>
        <visual name="">
            <origin xyz="0.2 0.425 0.0" rpy="1.5705 0.0 0.0" />
            <geometry>
                <cylinder radius="0.1" length="0.05" />
            </geometry>

        </visual>
        <collision>
            <origin xyz="0.0 0.0 0.0" rpy="0.0 0.0 0.0" />
            <geometry>
                <cylinder radius="0.1" length="0.05" />
            </geometry>
        </collision>
    </link>
    <joint name="right_wheel_front_joint" type="continuous">
        <origin xyz="0.0 -0.2 0.03" rpy="0.0 0.0 0.0" />
        <parent link="chassis" />
        <child link="right_wheel_front" />
        <axis xyz="0.0 0.0 0.0" />
    </joint>

<!--left wheel front-->

    <link name="left_wheel_front">
        <inertial>
            <origin xyz="0.0 0.0 0.0" rpy="0.0 0.0 0.0" />
            <mass value="1.0" />
            <inertia ixx="1.0" ixy="0.0" ixz="0.0" iyy="1.0" iyz="0.0" izz="1.0" />
        </inertial>
        <visual name="">
            <origin xyz="0.2 -0.425 0.0" rpy="1.5705 0.0 0.0" />
            <geometry>
                <cylinder radius="0.1" length="0.05" />
            </geometry>

        </visual>
        <collision>
            <origin xyz="0.0 0.0 0.0" rpy="0.0 0.0 0.0" />
            <geometry>
                <cylinder radius="0.1" length="0.05" />
            </geometry>
        </collision>
    </link>
    <joint name="left_wheel__front_joint" type="continuous">
        <origin xyz="0.0 0.2 0.03" rpy="0.0 0.0 0.0" />
        <parent link="chassis" />
        <child link="left_wheel_front" />
        <axis xyz="0.0 0.0 0.0" />
    </joint>

<!--leftt wheel back-->

    <link name="left_wheel_back">
        <inertial>
            <origin xyz="0.0 0.0 0.0" rpy="0.0 0.0 0.0" />
            <mass value="1.0" />
            <inertia ixx="1.0" ixy="0.0" ixz="0.0" iyy="1.0" iyz="0.0" izz="1.0" />
        </inertial>
        <visual name="">
            <origin xyz="-0.2 -0.425 0.0" rpy="1.5705 0.0 0.0" />
            <geometry>
                <cylinder radius="0.1" length="0.05" />
            </geometry>

        </visual>
        <collision>
            <origin xyz="0.0 0.0 0.0" rpy="0.0 0.0 0.0" />
            <geometry>
                <cylinder radius="0.1" length="0.05" />
            </geometry>
        </collision>
    </link>
    <joint name="left_wheel_joint_back" type="continuous">
        <origin xyz="0.0 0.2 0.03" rpy="0.0 0.0 0.0" />
        <parent link="chassis" />
        <child link="left_wheel_back" />
        <axis xyz="0.0 0.0 0.0" />
    </joint>

<!--right wheel back-->

    <link name="right_wheel_rear">
        <inertial>
            <origin xyz="0.0 0.0 0.0" rpy="0.0 0.0 0.0" />
            <mass value="1.0" />
            <inertia ixx="1.0" ixy="0.0" ixz="0.0" iyy="1.0" iyz="0.0" izz="1.0" />
        </inertial>
        <visual name="">
            <origin xyz="-0.2 0.025 0.0" rpy="1.5705 0.0 0.0" />
            <geometry>
                <cylinder radius="0.1" length="0.05" />
            </geometry>

        </visual>
        <collision>
            <origin xyz="0.0 0.0 0.0" rpy="0.0 0.0 0.0" />
            <geometry>
                <cylinder radius="0.1" length="0.05" />
            </geometry>
        </collision>
    </link>
    <joint name="right_wheel_joint_rear" type="continuous">
        <origin xyz="0.0 0.2 0.03" rpy="0.0 0.0 0.0" />
        <parent link="chassis" />
        <child link="right_wheel_rear" />
        <axis xyz="0.0 0.0 0.0" />
    </joint>

<!-- Attached Lider-->
       <link name="lider_link">
        <inertial>
            <origin xyz="0.0 0.0 0.0" rpy="0.0 0.0 0.0"/>
            <mass value="0.0"/>
            <inertia ixx="1.0" ixy="0.0" ixz="0.0" iyy="1.0" iyz="0.0" izz="1.0"/>
        </inertial>
        <visual name="">
            <origin xyz="0.13 0.0 0.18" rpy="0.0 0.0 0.0"/>
            <geometry>
                <cylinder radius="0.06" length="0.08"/>
            </geometry>
            <material name="">
                <color rgba="1.0 0.0 0.0 1.0"/>
                <texture filename=""/>
            </material>
        </visual>
        <collision>
            <origin xyz="0.13 0.0 0.2" rpy="0.0 0.0 0.0"/>
            <geometry>
                <cylinder radius="0.06" length="0.08"/>
            </geometry>
        </collision>
       </link>
       <joint name="lider_joint" type="fixed">
        <origin xyz="0.0 0.0 0.0" rpy="0.0 0.0 0.0"/>
        <parent link="chassis"/>
        <child link="lider_link"/>
       </joint>   
</robot>